2022-02-03 11:40:00,738 ERROR app Thread-1 (process_request_thread) : Exception on / [GET]
Traceback (most recent call last):
  File "C:\Users\a1csk\Desktop\School\C964 Capstone\Capstone_Final\venv\lib\site-packages\pandas\core\indexes\base.py", line 3361, in get_loc
    return self._engine.get_loc(casted_key)
  File "pandas\_libs\index.pyx", line 76, in pandas._libs.index.IndexEngine.get_loc
  File "pandas\_libs\index.pyx", line 108, in pandas._libs.index.IndexEngine.get_loc
  File "pandas\_libs\hashtable_class_helper.pxi", line 5198, in pandas._libs.hashtable.PyObjectHashTable.get_item
  File "pandas\_libs\hashtable_class_helper.pxi", line 5206, in pandas._libs.hashtable.PyObjectHashTable.get_item
KeyError: 'num_of_page'

The above exception was the direct cause of the following exception:

Traceback (most recent call last):
  File "C:\Users\a1csk\Desktop\School\C964 Capstone\Capstone_Final\venv\lib\site-packages\flask\app.py", line 2073, in wsgi_app
    response = self.full_dispatch_request()
  File "C:\Users\a1csk\Desktop\School\C964 Capstone\Capstone_Final\venv\lib\site-packages\flask\app.py", line 1518, in full_dispatch_request
    rv = self.handle_user_exception(e)
  File "C:\Users\a1csk\Desktop\School\C964 Capstone\Capstone_Final\venv\lib\site-packages\flask\app.py", line 1516, in full_dispatch_request
    rv = self.dispatch_request()
  File "C:\Users\a1csk\Desktop\School\C964 Capstone\Capstone_Final\venv\lib\site-packages\flask\app.py", line 1502, in dispatch_request
    return self.ensure_sync(self.view_functions[rule.endpoint])(**req.view_args)
  File "C:\Users\a1csk\Desktop\School\C964 Capstone\Capstone_Final\app.py", line 312, in draw_graphs
    for i in dataset["num_of_page"].head(100):
  File "C:\Users\a1csk\Desktop\School\C964 Capstone\Capstone_Final\venv\lib\site-packages\pandas\core\frame.py", line 3458, in __getitem__
    indexer = self.columns.get_loc(key)
  File "C:\Users\a1csk\Desktop\School\C964 Capstone\Capstone_Final\venv\lib\site-packages\pandas\core\indexes\base.py", line 3363, in get_loc
    raise KeyError(key) from err
KeyError: 'num_of_page'
2022-02-03 11:40:00,747 INFO werkzeug Thread-1 (process_request_thread) : 127.0.0.1 - - [03/Feb/2022 11:40:00] "[35m[1mGET / HTTP/1.1[0m" 500 -
2022-02-03 11:57:32,577 ERROR app Thread-2 (process_request_thread) : Exception on / [GET]
Traceback (most recent call last):
  File "C:\Users\a1csk\Desktop\School\C964 Capstone\Capstone_Final\venv\lib\site-packages\pandas\core\indexes\base.py", line 3361, in get_loc
    return self._engine.get_loc(casted_key)
  File "pandas\_libs\index.pyx", line 76, in pandas._libs.index.IndexEngine.get_loc
  File "pandas\_libs\index.pyx", line 108, in pandas._libs.index.IndexEngine.get_loc
  File "pandas\_libs\hashtable_class_helper.pxi", line 5198, in pandas._libs.hashtable.PyObjectHashTable.get_item
  File "pandas\_libs\hashtable_class_helper.pxi", line 5206, in pandas._libs.hashtable.PyObjectHashTable.get_item
KeyError: 'num_of_page'

The above exception was the direct cause of the following exception:

Traceback (most recent call last):
  File "C:\Users\a1csk\Desktop\School\C964 Capstone\Capstone_Final\venv\lib\site-packages\flask\app.py", line 2073, in wsgi_app
    response = self.full_dispatch_request()
  File "C:\Users\a1csk\Desktop\School\C964 Capstone\Capstone_Final\venv\lib\site-packages\flask\app.py", line 1518, in full_dispatch_request
    rv = self.handle_user_exception(e)
  File "C:\Users\a1csk\Desktop\School\C964 Capstone\Capstone_Final\venv\lib\site-packages\flask\app.py", line 1516, in full_dispatch_request
    rv = self.dispatch_request()
  File "C:\Users\a1csk\Desktop\School\C964 Capstone\Capstone_Final\venv\lib\site-packages\flask\app.py", line 1502, in dispatch_request
    return self.ensure_sync(self.view_functions[rule.endpoint])(**req.view_args)
  File "C:\Users\a1csk\Desktop\School\C964 Capstone\Capstone_Final\app.py", line 307, in draw_graphs
    for i in dataset["num_of_page"].head(100):
  File "C:\Users\a1csk\Desktop\School\C964 Capstone\Capstone_Final\venv\lib\site-packages\pandas\core\frame.py", line 3458, in __getitem__
    indexer = self.columns.get_loc(key)
  File "C:\Users\a1csk\Desktop\School\C964 Capstone\Capstone_Final\venv\lib\site-packages\pandas\core\indexes\base.py", line 3363, in get_loc
    raise KeyError(key) from err
KeyError: 'num_of_page'
2022-02-03 11:57:32,618 INFO werkzeug Thread-2 (process_request_thread) : 127.0.0.1 - - [03/Feb/2022 11:57:32] "[35m[1mGET / HTTP/1.1[0m" 500 -
2022-02-03 11:57:32,658 INFO werkzeug Thread-1 (process_request_thread) : 127.0.0.1 - - [03/Feb/2022 11:57:32] "[33mGET /favicon.ico HTTP/1.1[0m" 404 -
2022-02-03 12:00:20,734 ERROR app Thread-1 (process_request_thread) : Exception on / [GET]
Traceback (most recent call last):
  File "C:\Users\a1csk\Desktop\School\C964 Capstone\Capstone_Final\venv\lib\site-packages\pandas\core\indexes\base.py", line 3361, in get_loc
    return self._engine.get_loc(casted_key)
  File "pandas\_libs\index.pyx", line 76, in pandas._libs.index.IndexEngine.get_loc
  File "pandas\_libs\index.pyx", line 108, in pandas._libs.index.IndexEngine.get_loc
  File "pandas\_libs\hashtable_class_helper.pxi", line 5198, in pandas._libs.hashtable.PyObjectHashTable.get_item
  File "pandas\_libs\hashtable_class_helper.pxi", line 5206, in pandas._libs.hashtable.PyObjectHashTable.get_item
KeyError: 'num_of_page'

The above exception was the direct cause of the following exception:

Traceback (most recent call last):
  File "C:\Users\a1csk\Desktop\School\C964 Capstone\Capstone_Final\venv\lib\site-packages\flask\app.py", line 2073, in wsgi_app
    response = self.full_dispatch_request()
  File "C:\Users\a1csk\Desktop\School\C964 Capstone\Capstone_Final\venv\lib\site-packages\flask\app.py", line 1518, in full_dispatch_request
    rv = self.handle_user_exception(e)
  File "C:\Users\a1csk\Desktop\School\C964 Capstone\Capstone_Final\venv\lib\site-packages\flask\app.py", line 1516, in full_dispatch_request
    rv = self.dispatch_request()
  File "C:\Users\a1csk\Desktop\School\C964 Capstone\Capstone_Final\venv\lib\site-packages\flask\app.py", line 1502, in dispatch_request
    return self.ensure_sync(self.view_functions[rule.endpoint])(**req.view_args)
  File "C:\Users\a1csk\Desktop\School\C964 Capstone\Capstone_Final\app.py", line 306, in draw_graphs
    print(dataset["num_of_page"].head(5))
  File "C:\Users\a1csk\Desktop\School\C964 Capstone\Capstone_Final\venv\lib\site-packages\pandas\core\frame.py", line 3458, in __getitem__
    indexer = self.columns.get_loc(key)
  File "C:\Users\a1csk\Desktop\School\C964 Capstone\Capstone_Final\venv\lib\site-packages\pandas\core\indexes\base.py", line 3363, in get_loc
    raise KeyError(key) from err
KeyError: 'num_of_page'
2022-02-03 12:00:20,773 INFO werkzeug Thread-1 (process_request_thread) : 127.0.0.1 - - [03/Feb/2022 12:00:20] "[35m[1mGET / HTTP/1.1[0m" 500 -
2022-02-03 12:03:55,227 ERROR app Thread-1 (process_request_thread) : Exception on / [GET]
Traceback (most recent call last):
  File "C:\Users\a1csk\Desktop\School\C964 Capstone\Capstone_Final\venv\lib\site-packages\pandas\core\indexes\base.py", line 3361, in get_loc
    return self._engine.get_loc(casted_key)
  File "pandas\_libs\index.pyx", line 76, in pandas._libs.index.IndexEngine.get_loc
  File "pandas\_libs\index.pyx", line 108, in pandas._libs.index.IndexEngine.get_loc
  File "pandas\_libs\hashtable_class_helper.pxi", line 5198, in pandas._libs.hashtable.PyObjectHashTable.get_item
  File "pandas\_libs\hashtable_class_helper.pxi", line 5206, in pandas._libs.hashtable.PyObjectHashTable.get_item
KeyError: 'num_of_page'

The above exception was the direct cause of the following exception:

Traceback (most recent call last):
  File "C:\Users\a1csk\Desktop\School\C964 Capstone\Capstone_Final\venv\lib\site-packages\flask\app.py", line 2073, in wsgi_app
    response = self.full_dispatch_request()
  File "C:\Users\a1csk\Desktop\School\C964 Capstone\Capstone_Final\venv\lib\site-packages\flask\app.py", line 1518, in full_dispatch_request
    rv = self.handle_user_exception(e)
  File "C:\Users\a1csk\Desktop\School\C964 Capstone\Capstone_Final\venv\lib\site-packages\flask\app.py", line 1516, in full_dispatch_request
    rv = self.dispatch_request()
  File "C:\Users\a1csk\Desktop\School\C964 Capstone\Capstone_Final\venv\lib\site-packages\flask\app.py", line 1502, in dispatch_request
    return self.ensure_sync(self.view_functions[rule.endpoint])(**req.view_args)
  File "C:\Users\a1csk\Desktop\School\C964 Capstone\Capstone_Final\app.py", line 308, in draw_graphs
    for i in dataset["num_of_page"].head(100):
  File "C:\Users\a1csk\Desktop\School\C964 Capstone\Capstone_Final\venv\lib\site-packages\pandas\core\frame.py", line 3458, in __getitem__
    indexer = self.columns.get_loc(key)
  File "C:\Users\a1csk\Desktop\School\C964 Capstone\Capstone_Final\venv\lib\site-packages\pandas\core\indexes\base.py", line 3363, in get_loc
    raise KeyError(key) from err
KeyError: 'num_of_page'
2022-02-03 12:03:55,233 INFO werkzeug Thread-1 (process_request_thread) : 127.0.0.1 - - [03/Feb/2022 12:03:55] "[35m[1mGET / HTTP/1.1[0m" 500 -
2022-02-03 12:04:32,986 INFO werkzeug Thread-1 (process_request_thread) : 127.0.0.1 - - [03/Feb/2022 12:04:32] "GET / HTTP/1.1" 200 -
